<?xml version="1.0" ?>
<!-- =================================================================================== -->
<!-- |    This document was autogenerated by xacro from bmw_robot.xacro                | -->
<!-- |    EDITING THIS FILE BY HAND IS NOT RECOMMENDED                                 | -->
<!-- =================================================================================== -->
<robot name="BMW_Car">
  <!-- materials exactly as in the URDF -->
  <material name="blue">
    <color rgba="0 0.2 0.9 1"/>
  </material>
  <material name="gray">
    <color rgba="0.1 0.1 0.1 1"/>
  </material>
  <material name="darkBlue">
    <color rgba="0 0 0.1 1"/>
  </material>
  <link name="dummy_link"/>
  <link name="chassis">
    <visual>
      <geometry>
        <box size="0.6 0.7 0.1"/>
      </geometry>
      <origin rpy="0 0 1.57" xyz="0 0 0"/>
      <material name="darkBlue"/>
    </visual>
    <collision>
      <geometry>
        <box size="0.6 0.7 0.1"/>
      </geometry>
      <origin rpy="0 0 1.57" xyz="0 0 0"/>
    </collision>
    <inertial>
      <origin rpy="0 0 1.57" xyz="0 0 0"/>
      <mass value="0.1"/>
      <inertia ixx="0.004166666666666666" ixy="0" ixz="0" iyy="0.0030833333333333333" iyz="0" izz="0.007083333333333332"/>
    </inertial>
  </link>
  <joint name="chassis_joint" type="fixed">
    <parent link="dummy_link"/>
    <child link="chassis"/>
    <origin rpy="0 0 0" xyz="0 0 0"/>
  </joint>
  <gazebo reference="chassis">
    <material>Gazebo/DarkMagentaTransparent</material>
  </gazebo>
  <link name="LF_wheel">
    <inertial>
      <origin rpy="0 0 0" xyz="0 0 0"/>
      <mass value="0.05"/>
      <inertia ixx="0.0005204166666666667" ixy="0" ixz="0" iyy="0.0005204166666666667" iyz="0" izz="0.0010000000000000002"/>
    </inertial>
    <visual>
      <origin rpy="0 0 0" xyz="0 0 0"/>
      <geometry>
        <cylinder length="0.07" radius="0.2"/>
      </geometry>
      <material name="gray"/>
    </visual>
    <collision>
      <origin rpy="0 0 0" xyz="0 0 0"/>
      <!-- sphere collision as in URDF -->
      <geometry>
        <sphere radius="0.2"/>
      </geometry>
    </collision>
  </link>
  <joint name="LF_wheel_joint" type="continuous">
    <parent link="chassis"/>
    <child link="LF_wheel"/>
    <origin rpy="0 1.57 -1.57" xyz="0.333 0.333 0"/>
    <axis xyz="0 0 -1"/>
  </joint>
  <gazebo reference="LF_wheel">
    <material>Gazebo/Black</material>
    <mu1 value="0.2"/>
    <mu2 value="0.2"/>
  </gazebo>
  <link name="LB_wheel">
    <inertial>
      <origin rpy="0 0 0" xyz="0 0 0"/>
      <mass value="0.05"/>
      <inertia ixx="0.0005204166666666667" ixy="0" ixz="0" iyy="0.0005204166666666667" iyz="0" izz="0.0010000000000000002"/>
    </inertial>
    <visual>
      <origin rpy="0 0 0" xyz="0 0 0"/>
      <geometry>
        <cylinder length="0.07" radius="0.2"/>
      </geometry>
      <material name="gray"/>
    </visual>
    <collision>
      <origin rpy="0 0 0" xyz="0 0 0"/>
      <!-- sphere collision as in URDF -->
      <geometry>
        <sphere radius="0.2"/>
      </geometry>
    </collision>
  </link>
  <joint name="LB_wheel_joint" type="continuous">
    <parent link="chassis"/>
    <child link="LB_wheel"/>
    <origin rpy="0 1.57 -1.57" xyz="-0.333 0.333 0"/>
    <axis xyz="0 0 -1"/>
  </joint>
  <gazebo reference="LB_wheel">
    <material>Gazebo/Black</material>
    <mu1 value="0.2"/>
    <mu2 value="0.2"/>
  </gazebo>
  <link name="RF_wheel">
    <inertial>
      <origin rpy="0 0 0" xyz="0 0 0"/>
      <mass value="0.05"/>
      <inertia ixx="0.0005204166666666667" ixy="0" ixz="0" iyy="0.0005204166666666667" iyz="0" izz="0.0010000000000000002"/>
    </inertial>
    <visual>
      <origin rpy="0 0 0" xyz="0 0 0"/>
      <geometry>
        <cylinder length="0.07" radius="0.2"/>
      </geometry>
      <material name="gray"/>
    </visual>
    <collision>
      <origin rpy="0 0 0" xyz="0 0 0"/>
      <!-- sphere collision as in URDF -->
      <geometry>
        <sphere radius="0.2"/>
      </geometry>
    </collision>
  </link>
  <joint name="RF_wheel_joint" type="continuous">
    <parent link="chassis"/>
    <child link="RF_wheel"/>
    <origin rpy="0 1.57 -1.57" xyz="0.333 -0.333 0"/>
    <axis xyz="0 0 -1"/>
  </joint>
  <gazebo reference="RF_wheel">
    <material>Gazebo/Black</material>
    <mu1 value="0.2"/>
    <mu2 value="0.2"/>
  </gazebo>
  <link name="RB_wheel">
    <inertial>
      <origin rpy="0 0 0" xyz="0 0 0"/>
      <mass value="0.05"/>
      <inertia ixx="0.0005204166666666667" ixy="0" ixz="0" iyy="0.0005204166666666667" iyz="0" izz="0.0010000000000000002"/>
    </inertial>
    <visual>
      <origin rpy="0 0 0" xyz="0 0 0"/>
      <geometry>
        <cylinder length="0.07" radius="0.2"/>
      </geometry>
      <material name="gray"/>
    </visual>
    <collision>
      <origin rpy="0 0 0" xyz="0 0 0"/>
      <!-- sphere collision as in URDF -->
      <geometry>
        <sphere radius="0.2"/>
      </geometry>
    </collision>
  </link>
  <joint name="RB_wheel_joint" type="continuous">
    <parent link="chassis"/>
    <child link="RB_wheel"/>
    <origin rpy="0 1.57 -1.57" xyz="-0.333 -0.333 0"/>
    <axis xyz="0 0 -1"/>
  </joint>
  <gazebo reference="RB_wheel">
    <material>Gazebo/Black</material>
    <mu1 value="0.2"/>
    <mu2 value="0.2"/>
  </gazebo>
  <link name="lidar">
    <visual>
      <geometry>
        <cylinder length="0.25" radius="0.15"/>
      </geometry>
      <origin rpy="0 0 0" xyz="-0.16 0 0.1"/>
      <material name="blue"/>
    </visual>
    <collision>
      <geometry>
        <cylinder length="0.25" radius="0.15"/>
      </geometry>
      <origin rpy="0 0 0" xyz="-0.16 0 0.1"/>
    </collision>
    <inertial>
      <origin rpy="0 0 0" xyz="-0.16 0 0.1"/>
      <mass value="0.1"/>
      <inertia ixx="0.0010833333333333333" ixy="0" ixz="0" iyy="0.0010833333333333333" iyz="0" izz="0.001125"/>
    </inertial>
  </link>
  <!-- Joint (offsets are in link origins, joint origin is zero) -->
  <joint name="lidar_joint" type="fixed">
    <parent link="chassis"/>
    <child link="lidar"/>
    <origin rpy="0 0 0" xyz="0 0 0"/>
  </joint>
  <!-- Gazebo visual material (from URDF) -->
  <gazebo reference="lidar">
    <material>Gazebo/Indigo</material>
  </gazebo>
  <link name="camera">
    <visual>
      <geometry>
        <box size="0.15 0.15 0.08"/>
      </geometry>
      <origin rpy="0 0 0" xyz="0.2 0 0.05"/>
      <material name="blue"/>
    </visual>
    <collision>
      <geometry>
        <box size="0.15 0.15 0.08"/>
      </geometry>
      <origin rpy="0 0 0" xyz="0.2 0 0.05"/>
    </collision>
    <inertial>
      <origin rpy="0 0 0" xyz="0 0 0"/>
      <mass value="0.05"/>
      <inertia ixx="0.00012041666666666666" ixy="0" ixz="0" iyy="0.00012041666666666666" iyz="0" izz="0.0001875"/>
    </inertial>
  </link>
  <joint name="camera_joint" type="fixed">
    <parent link="chassis"/>
    <child link="camera"/>
    <origin rpy="0 0 0" xyz="0 0 0"/>
  </joint>
  <gazebo reference="camera">
    <material>Gazebo/Indigo</material>
  </gazebo>
  <!-- Add Gazebo plugins (enable when you want motion + sensors in sim) -->
  <!-- <xacro:add_plugins/> -->
</robot>
